{
 "cells": [
  {
   "cell_type": "code",
   "execution_count": null,
   "metadata": {},
   "outputs": [
    {
     "ename": "",
     "evalue": "",
     "output_type": "error",
     "traceback": [
      "\u001b[1;31mThe kernel failed to start as the Python Environment 'venv (Python 3.12.1)' is no longer available. Consider selecting another kernel or refreshing the list of Python Environments."
     ]
    }
   ],
   "source": [
    "import pandas as pd\n",
    "\n"
   ]
  },
  {
   "cell_type": "code",
   "execution_count": null,
   "metadata": {},
   "outputs": [
    {
     "ename": "",
     "evalue": "",
     "output_type": "error",
     "traceback": [
      "\u001b[1;31mThe kernel failed to start as the Python Environment 'venv (Python 3.12.1)' is no longer available. Consider selecting another kernel or refreshing the list of Python Environments."
     ]
    }
   ],
   "source": [
    "import os\n",
    "\n",
    "# Remove any existing backend configuration that might be causing issues\n",
    "os.environ.pop('MPLBACKEND', None)\n",
    "\n",
    "# Import matplotlib and set a safe backend\n",
    "import matplotlib\n",
    "#matplotlib.use('agg')  # Use 'agg' backend which does not require a graphical interface\n",
    "\n",
    "import matplotlib.pyplot as plt\n"
   ]
  },
  {
   "cell_type": "code",
   "execution_count": null,
   "metadata": {},
   "outputs": [
    {
     "ename": "",
     "evalue": "",
     "output_type": "error",
     "traceback": [
      "\u001b[1;31mThe kernel failed to start as the Python Environment 'venv (Python 3.12.1)' is no longer available. Consider selecting another kernel or refreshing the list of Python Environments."
     ]
    }
   ],
   "source": [
    "# Load the data\n",
    "data = pd.read_csv('Community_Crime_and_Disorder_Statistics__2012-2019_.csv')\n",
    "print(data.head())\n",
    "\n"
   ]
  },
  {
   "cell_type": "code",
   "execution_count": null,
   "metadata": {},
   "outputs": [
    {
     "ename": "",
     "evalue": "",
     "output_type": "error",
     "traceback": [
      "\u001b[1;31mThe kernel failed to start as the Python Environment 'venv (Python 3.12.1)' is no longer available. Consider selecting another kernel or refreshing the list of Python Environments."
     ]
    }
   ],
   "source": [
    "print(data['Date'].dtype)"
   ]
  },
  {
   "cell_type": "code",
   "execution_count": null,
   "metadata": {},
   "outputs": [
    {
     "ename": "",
     "evalue": "",
     "output_type": "error",
     "traceback": [
      "\u001b[1;31mThe kernel failed to start as the Python Environment 'venv (Python 3.12.1)' is no longer available. Consider selecting another kernel or refreshing the list of Python Environments."
     ]
    }
   ],
   "source": [
    "data['Date'] = pd.to_datetime(data['Date'])\n",
    "\n",
    "# Verificar novamente o tipo de dados após a conversão\n",
    "print(data['Date'].dtype)"
   ]
  },
  {
   "cell_type": "code",
   "execution_count": null,
   "metadata": {},
   "outputs": [
    {
     "ename": "",
     "evalue": "",
     "output_type": "error",
     "traceback": [
      "\u001b[1;31mThe kernel failed to start as the Python Environment 'venv (Python 3.12.1)' is no longer available. Consider selecting another kernel or refreshing the list of Python Environments."
     ]
    }
   ],
   "source": [
    "# Display the first few rows of the 'Date' column to verify the format\n",
    "print(data['Date'].head())"
   ]
  },
  {
   "cell_type": "code",
   "execution_count": null,
   "metadata": {},
   "outputs": [
    {
     "ename": "",
     "evalue": "",
     "output_type": "error",
     "traceback": [
      "\u001b[1;31mThe kernel failed to start as the Python Environment 'venv (Python 3.12.1)' is no longer available. Consider selecting another kernel or refreshing the list of Python Environments."
     ]
    }
   ],
   "source": [
    "# Set the 'Date' column as the index of the DataFrame\n",
    "data.set_index('Date', inplace=True) # essential for time series"
   ]
  },
  {
   "cell_type": "code",
   "execution_count": null,
   "metadata": {},
   "outputs": [
    {
     "ename": "",
     "evalue": "",
     "output_type": "error",
     "traceback": [
      "\u001b[1;31mThe kernel failed to start as the Python Environment 'venv (Python 3.12.1)' is no longer available. Consider selecting another kernel or refreshing the list of Python Environments."
     ]
    }
   ],
   "source": [
    "from statsmodels.tsa.seasonal import seasonal_decompose\n",
    "# Decompose the time series\n",
    "# Use 'Count' as the column of interest for this example\n",
    "decomposed = seasonal_decompose(data['Crime Count'], model='additive', period=12)\n",
    "\n",
    "# Plot the decomposed components\n",
    "decomposed.plot()\n",
    "plt.show()"
   ]
  },
  {
   "cell_type": "code",
   "execution_count": null,
   "metadata": {},
   "outputs": [
    {
     "ename": "",
     "evalue": "",
     "output_type": "error",
     "traceback": [
      "\u001b[1;31mThe kernel failed to start as the Python Environment 'venv (Python 3.12.1)' is no longer available. Consider selecting another kernel or refreshing the list of Python Environments."
     ]
    }
   ],
   "source": []
  },
  {
   "cell_type": "code",
   "execution_count": null,
   "metadata": {},
   "outputs": [
    {
     "ename": "",
     "evalue": "",
     "output_type": "error",
     "traceback": [
      "\u001b[1;31mThe kernel failed to start as the Python Environment 'venv (Python 3.12.1)' is no longer available. Consider selecting another kernel or refreshing the list of Python Environments."
     ]
    }
   ],
   "source": []
  },
  {
   "cell_type": "code",
   "execution_count": null,
   "metadata": {},
   "outputs": [
    {
     "ename": "",
     "evalue": "",
     "output_type": "error",
     "traceback": [
      "\u001b[1;31mThe kernel failed to start as the Python Environment 'venv (Python 3.12.1)' is no longer available. Consider selecting another kernel or refreshing the list of Python Environments."
     ]
    }
   ],
   "source": []
  },
  {
   "cell_type": "code",
   "execution_count": null,
   "metadata": {},
   "outputs": [
    {
     "ename": "",
     "evalue": "",
     "output_type": "error",
     "traceback": [
      "\u001b[1;31mThe kernel failed to start as the Python Environment 'venv (Python 3.12.1)' is no longer available. Consider selecting another kernel or refreshing the list of Python Environments."
     ]
    }
   ],
   "source": []
  },
  {
   "cell_type": "code",
   "execution_count": null,
   "metadata": {},
   "outputs": [
    {
     "ename": "",
     "evalue": "",
     "output_type": "error",
     "traceback": [
      "\u001b[1;31mThe kernel failed to start as the Python Environment 'venv (Python 3.12.1)' is no longer available. Consider selecting another kernel or refreshing the list of Python Environments."
     ]
    }
   ],
   "source": [
    "# Carregar os dados\n",
    "data = pd.read_csv('Community_Crime_and_Disorder_Statistics__2012-2019_.csv', index_col='date', parse_dates=True)\n",
    "\n",
    "# Configurar frequência mensal\n",
    "data = data.asfreq('M')\n",
    "\n",
    "# Visualizar os dados\n",
    "data.plot(title='Dados Temporais')\n",
    "plt.xlabel('Data')\n",
    "plt.ylabel('Valor')\n",
    "plt.show()\n"
   ]
  },
  {
   "cell_type": "code",
   "execution_count": null,
   "metadata": {},
   "outputs": [
    {
     "ename": "",
     "evalue": "",
     "output_type": "error",
     "traceback": [
      "\u001b[1;31mThe kernel failed to start as the Python Environment 'venv (Python 3.12.1)' is no longer available. Consider selecting another kernel or refreshing the list of Python Environments."
     ]
    }
   ],
   "source": [
    "calg_crime = pd.read_csv(\"Community_Crime_and_Disorder_Statistics__2012-2019_.csv\")\n"
   ]
  },
  {
   "cell_type": "code",
   "execution_count": null,
   "metadata": {},
   "outputs": [
    {
     "ename": "",
     "evalue": "",
     "output_type": "error",
     "traceback": [
      "\u001b[1;31mThe kernel failed to start as the Python Environment 'venv (Python 3.12.1)' is no longer available. Consider selecting another kernel or refreshing the list of Python Environments."
     ]
    }
   ],
   "source": [
    "print(calg_crime.head())\n",
    "print(calg_crime.columns)\n"
   ]
  },
  {
   "cell_type": "code",
   "execution_count": null,
   "metadata": {},
   "outputs": [
    {
     "ename": "",
     "evalue": "",
     "output_type": "error",
     "traceback": [
      "\u001b[1;31mThe kernel failed to start as the Python Environment 'venv (Python 3.12.1)' is no longer available. Consider selecting another kernel or refreshing the list of Python Environments."
     ]
    }
   ],
   "source": [
    "calg_crime1 = calg_crime.drop(columns=[\"ID\", \"Resident.Count\", \"Community.Center.Point\"])\n",
    "print(calg_crime1.head())\n"
   ]
  },
  {
   "cell_type": "code",
   "execution_count": null,
   "metadata": {},
   "outputs": [
    {
     "ename": "",
     "evalue": "",
     "output_type": "error",
     "traceback": [
      "\u001b[1;31mThe kernel failed to start as the Python Environment 'venv (Python 3.12.1)' is no longer available. Consider selecting another kernel or refreshing the list of Python Environments."
     ]
    }
   ],
   "source": [
    "library(forecast)\n",
    "library(ggplot2)\n",
    "\n",
    "data <- ts(data, frequency=12, start=c(2020,1))\n",
    "plot(data)\n"
   ]
  },
  {
   "cell_type": "code",
   "execution_count": null,
   "metadata": {},
   "outputs": [
    {
     "ename": "",
     "evalue": "",
     "output_type": "error",
     "traceback": [
      "\u001b[1;31mThe kernel failed to start as the Python Environment 'venv (Python 3.12.1)' is no longer available. Consider selecting another kernel or refreshing the list of Python Environments."
     ]
    }
   ],
   "source": []
  },
  {
   "cell_type": "code",
   "execution_count": null,
   "metadata": {},
   "outputs": [
    {
     "ename": "",
     "evalue": "",
     "output_type": "error",
     "traceback": [
      "\u001b[1;31mThe kernel failed to start as the Python Environment 'venv (Python 3.12.1)' is no longer available. Consider selecting another kernel or refreshing the list of Python Environments."
     ]
    }
   ],
   "source": []
  },
  {
   "cell_type": "code",
   "execution_count": null,
   "metadata": {},
   "outputs": [
    {
     "ename": "",
     "evalue": "",
     "output_type": "error",
     "traceback": [
      "\u001b[1;31mThe kernel failed to start as the Python Environment 'venv (Python 3.12.1)' is no longer available. Consider selecting another kernel or refreshing the list of Python Environments."
     ]
    }
   ],
   "source": []
  },
  {
   "cell_type": "code",
   "execution_count": null,
   "metadata": {},
   "outputs": [
    {
     "ename": "",
     "evalue": "",
     "output_type": "error",
     "traceback": [
      "\u001b[1;31mThe kernel failed to start as the Python Environment 'venv (Python 3.12.1)' is no longer available. Consider selecting another kernel or refreshing the list of Python Environments."
     ]
    }
   ],
   "source": []
  },
  {
   "cell_type": "code",
   "execution_count": null,
   "metadata": {},
   "outputs": [
    {
     "ename": "",
     "evalue": "",
     "output_type": "error",
     "traceback": [
      "\u001b[1;31mThe kernel failed to start as the Python Environment 'venv (Python 3.12.1)' is no longer available. Consider selecting another kernel or refreshing the list of Python Environments."
     ]
    }
   ],
   "source": []
  }
 ],
 "metadata": {
  "kernelspec": {
   "display_name": "venv",
   "language": "python",
   "name": "python3"
  },
  "language_info": {
   "codemirror_mode": {
    "name": "ipython",
    "version": 3
   },
   "file_extension": ".py",
   "mimetype": "text/x-python",
   "name": "python",
   "nbconvert_exporter": "python",
   "pygments_lexer": "ipython3",
   "version": "3.12.1"
  }
 },
 "nbformat": 4,
 "nbformat_minor": 2
}
